Workbook

Sheet Task-1(Data-Quality-Audit)
A1: Data Quality Assessment
A3: Total Orders | B3: =COUNTA(Orders!A2:A251) -> 250 | C3: Duplicate Oders | D3: 70 | E3: Inconsistent Date Formats | F3: 5
A4: Blank Values | C4: Country Variations | E4: Negative Quantity Orders | F4: 12
A5: Customer Name | B5: =COUNTBLANK(Orders!D2:D2036) -> 15 | C5: United States | D5: 4 | E5: Test Orders | F5: None
A6: Customer Email | B6: =COUNTBLANK(Orders!F2:F2036) -> 121 | C6: United Kindom | D6: 4 | E6: Currency as Text | F6: None
A7: Product Name | B7: =COUNTBLANK(Orders!G2:G2036) -> 0 | C7: Germany | D7: 2
A8: Category | B8: =COUNTBLANK(Orders!H2:H2036) -> 0 | C8: Australia | D8: 2
A9: SKU | B9: =COUNTBLANK(Orders!I2:I2036) -> 0 | C9: Canada | D9: 2
A10: Quantity | B10: =COUNTBLANK(Orders!J2:J2036) -> 0 | C10: Pakistan | D10: 2
A11: Unit Price | B11: =COUNTBLANK(Orders!K2:K2036) -> 0
A12: Discount Code | B12: =COUNTBLANK(Orders!L2:L2036) -> 910
A13: Discount Amount | B13: =COUNTBLANK(Orders!M2:M2036) -> 0
A14: Shipping | B14: =COUNTBLANK(Orders!N2:N2036) -> 0
A15: Total | B15: =COUNTBLANK(Orders!O2:O2036) -> 0
A16: Payment Method | B16: =COUNTBLANK(Orders!P2:P2036) -> 0
A17: Channel | B17: =COUNTBLANK(Orders!Q2:Q2036) -> 0
A18: Order status | B18: =COUNTBLANK(Orders!R2:R2036) -> 0
A19: Country | B19: =COUNTBLANK(Orders!#REF!) -> #REF!
A20: State | B20: =COUNTBLANK(Orders!T2:T2036) -> 1054
A21: City | B21: =COUNTBLANK(Orders!V2:V2036) -> 0

Sheet Cleaning Tasks
A2: Sales by Country | D2: Missing States Probem | G2: Missing Customer Emails
A3: Row Labels | B3: Sum of Sales | D3: Status | E3: Count
A4: Australia | B4: 1844.37 | D4: Valid | E4: =COUNTIF(Orders!U:U,D4) -> 981 | G4: Total Orders | H4: =COUNTA(Orders!A2:A2036) -> 2035
A5: Canada | B5: 1595.49 | D5: Missing | E5: =COUNTIF(Orders!U:U,D5) -> 0 | G5: Missing Emails | H5: =COUNTBLANK(Orders!F2:F2036) -> 121
A6: Germany | B6: 1191.28 | D6: Not Required | E6: =COUNTIF(Orders!U:U,D6) -> 1054 | G6: Missing Email % | H6: =COUNTBLANK(Orders!F2:F2036)/COUNTA(Orders!A2:A2036) -> 0.059459459
A7: Pakistan | B7: 1167.83 | G7: Emails status by differet channels
A8: United Kingdom | B8: 1311.68 | G8: Count of Order ID | H8: Column Labels
A9: United States | B9: 6345.76 | G9: Row Labels | H9: Email Available | I9: Missing Email | J9: Grand Total
A10: Grand Total | B10: 13456.41 | G10: Online Store | H10: 928 | I10: 65 | J10: 993
G11: Facebook | H11: 332 | I11: 24 | J11: 356
G12: POS | H12: 309 | I12: 20 | J12: 329
G13: Instagram | H13: 345 | I13: 12 | J13: 357
G14: Grand Total | H14: 1914 | I14: 121 | J14: 2035

Sheet Orders
A1: Order ID | B1: Formatted Order Date | C1: Order Date | D1: Customer Name | E1: Email Status | F1: Customer Email | G1: Product Name | H1: Category | I1: SKU | J1: Quantity | K1: Unit Price | L1: Discount Code | M1: Discount Amount | N1: Shipping | O1: Total | P1: Payment Method | Q1: Channel | R1: Order Status | S1: Country | T1: State | U1: State Status | V1: City
A2: #1042 | B2: =IF(ISNUMBER(C2),C2,DATEVALUE(SUBSTITUTE(TRIM(C2),CHAR(160)," "))) -> 46238.58 | C2: 46238.58 | D2: Angie Martin | E2: =IF(TRIM(F2)="","Missing Email","Email Available") -> Email Available | F2: angie.martin506@icloud.com | G2: Running Shoes - Women's | H2: Footwear | I2: FTW-RUN-W | J2: -1 | K2: 54.99 | L2: VIP15 | M2: 8.25 | N2: 5.99 | O2: 52.73 | P2: PayPal | Q2: Online Store | R2: fulfilled | S2: Pakistan | U2: =IF(AND(S2="United States",T2=""),"Missing state",IF(T2="","Not Required","Valid")) -> Not Required | V2: West Travis
A3: #1083 | B3: =IF(ISNUMBER(C3),C3,DATEVALUE(SUBSTITUTE(TRIM(C3),CHAR(160)," "))) -> 46238.58 | C3: 46238.58 | D3: Johnathan Sloan | E3: =IF(TRIM(F3)="","Missing Email","Email Available") -> Email Available | F3: johnathan.sloan721@outlook.com | G3: Running Shoes - Men's | H3: Footwear | I3: FTW-RUN-M | J3: -1 | K3: 54.99 | L3: SAVE20 | M3: $11.00 | N3: 5.99 | O3: 49.98 | P3: Apple Pay | Q3: Online Store | R3: fulfilled | S3: Pakistan | U3: =IF(AND(S3="United States",T3=""),"Missing state",IF(T3="","Not Required","Valid")) -> Not Required | V3: Robertborough
A4: #1371 | B4: =IF(ISNUMBER(C4),C4,DATEVALUE(SUBSTITUTE(TRIM(C4),CHAR(160)," "))) -> 46238.583 | C4: 46238.583 | D4: Andrew Vargas | E4: =IF(TRIM(F4)="","Missing Email","Email Available") -> Email Available | F4: andrew.vargas381@outlook.com | G4: Hooded Sweatshirt | H4: Apparel | I4: APR-HOD-GRY | J4: -1 | K4: 34.99 | M4: 0 | N4: 4.99 | O4: 39.98 | P4: PayPal | Q4: Online Store | R4: cancelled | S4: Canada | U4: =IF(AND(S4="United States",T4=""),"Missing state",IF(T4="","Not Required","Valid")) -> Not Required | V4: Port Jasmineview
A5: #1463 | B5: =IF(ISNUMBER(C5),C5,DATEVALUE(SUBSTITUTE(TRIM(C5),CHAR(160)," "))) -> 46238.581 | C5: 46238.581 | D5: Conway, Brittney | E5: =IF(TRIM(F5)="","Missing Email","Email Available") -> Email Available | F5: brittney.conway383@outlook.com | G5: Yoga Mat - Extra Thick | H5: Sports & Outdoors | I5: SP-YGM-EX | J5: -2 | K5: 22.99 | M5: $0.00 | N5: 7.99 | O5: 53.97 | P5: Apple Pay | Q5: Online Store | R5: fulfilled | S5: United States | T5: Texas | U5: =IF(AND(S5="United States",T5=""),"Missing state",IF(T5="","Not Required","Valid")) -> Valid | V5: North Nathan
A6: #1472 | B6: =IF(ISNUMBER(C6),C6,DATEVALUE(SUBSTITUTE(TRIM(C6),CHAR(160)," "))) -> 46120 | C6: 08/04/2026 | D6: Christy Phillips | E6: =IF(TRIM(F6)="","Missing Email","Email Available") -> Email Available | F6: christy.phillips291@gmail.com | G6: Hooded Sweatshirt | H6: Apparel | I6: APR-HOD-GRY | J6: -1 | K6: 34.99 | L6: VIP15 | M6: 5.25 | N6: 7.99 | O6: 37.73 | P6: Apple Pay | Q6: POS | R6: cancelled | S6: Pakistan | U6: =IF(AND(S6="United States",T6=""),"Missing state",IF(T6="","Not Required","Valid")) -> Not Required | V6: New Claire
A7: #1632 | B7: =IF(ISNUMBER(C7),C7,DATEVALUE(SUBSTITUTE(TRIM(C7),CHAR(160)," "))) -> 46120 | C7: 46120 | D7: Kenneth Morgan | E7: =IF(TRIM(F7)="","Missing Email","Email Available") -> Email Available | F7: kenneth.morgan181@outlook.com | G7: Backpack - 25L | H7: Accessories | I7: ACC-BPK-25L | J7: -3 | K7: 32.99 | L7: WELCOME10 | M7: 9.9 | N7: 0 | O7: 89.07 | P7: Apple Pay | Q7: Online Store | R7: fulfilled | S7: United States | T7: Arizona | U7: =IF(AND(S7="United States",T7=""),"Missing state",IF(T7="","Not Required","Valid")) -> Valid | V7: West David
A8: #1836 | B8: =IF(ISNUMBER(C8),C8,DATEVALUE(SUBSTITUTE(TRIM(C8),CHAR(160)," "))) -> 46238.586 | C8: 46238.586 | D8: Sergio Turner | E8: =IF(TRIM(F8)="","Missing Email","Email Available") -> Email Available | F8: sergio.turner744@outlook.com | G8: Wireless Mouse | H8: Electronics | I8: ELC-MSE-WL | J8: -2 | K8: 11.99 | M8: 0 | N8: 4.99 | O8: 28.97 | P8: Credit Card | Q8: Facebook | R8: fulfilled | S8: Germany | U8: =IF(AND(S8="United States",T8=""),"Missing state",IF(T8="","Not Required","Valid")) -> Not Required | V8: Fordburgh
A9: #2008 | B9: =IF(ISNUMBER(C9),C9,DATEVALUE(SUBSTITUTE(TRIM(C9),CHAR(160)," "))) -> 46238.589 | C9: 46238.589 | D9: Jacob Gibbs | E9: =IF(TRIM(F9)="","Missing Email","Email Available") -> Email Available | F9: jacob.gibbs527@gmail.com | G9: Classic Cotton T-Shirt | H9: Apparel | I9: TSH-BLK-M | J9: -2 | K9: 14.99 | M9: 0 | N9: 4.99 | O9: 34.97 | P9: Shopify Payments | Q9: Online Store | R9: fulfilled | S9: United States | T9: North Carolina | U9: =IF(AND(S9="United States",T9=""),"Missing state",IF(T9="","Not Required","Valid")) -> Valid | V9: Keyburgh
A10: #2485 | B10: =IF(ISNUMBER(C10),C10,DATEVALUE(SUBSTITUTE(TRIM(C10),CHAR(160)," "))) -> 46238.587 | C10: 46238.587 | D10: George Gould | E10: =IF(TRIM(F10)="","Missing Email","Email Available") -> Email Available | F10: george.gould10@yahoo.com | G10: Running Shoes - Women's | H10: Footwear | I10: FTW-RUN-W | J10: -1 | K10: $54.99 | M10: 0 | N10: 7.99 | O10: 62.98 | P10: Google Pay | Q10: Online Store | R10: fulfilled | S10: Canada | U10: =IF(AND(S10="United States",T10=""),"Missing state",IF(T10="","Not Required","Valid")) -> Not Required | V10: Port Jenniferburgh
A11: #2687 | B11: =IF(ISNUMBER(C11),C11,DATEVALUE(SUBSTITUTE(TRIM(C11),CHAR(160)," "))) -> 46238.583 | C11: 46238.583 | D11: Karen Bautista | E11: =IF(TRIM(F11)="","Missing Email","Email Available") -> Email Available | F11: karen.bautista779@icloud.com | G11: Vitamin C Serum 30ml | H11: Beauty | I11: BTY-SRM-30 | J11: -1 | K11: 24.99 | M11: 0 | N11: 5.99 | O11: 30.98 | P11: Apple Pay | Q11: Online Store | R11: fulfilled | S11: United States | T11: Washington | U11: =IF(AND(S11="United States",T11=""),"Missing state",IF(T11="","Not Required","Valid")) -> Valid | V11: Patrickmouth
A12: #2862 | B12: =IF(ISNUMBER(C12),C12,DATEVALUE(SUBSTITUTE(TRIM(C12),CHAR(160)," "))) -> 46238 | C12: 2026-08-04 | D12: Linda Scott | E12: =IF(TRIM(F12)="","Missing Email","Email Available") -> Email Available | F12: linda.scott2@icloud.com | G12: Vitamin C Serum 30ml | H12: Beauty | I12: BTY-SRM-30 | J12: -1 | K12: 24.99 | M12: 0 | N12: 4.99 | O12: 29.98 | P12: Google Pay | Q12: Facebook | R12: fulfilled | S12: Canada | U12: =IF(AND(S12="United States",T12=""),"Missing state",IF(T12="","Not Required","Valid")) -> Not Required | V12: South Lisaton
A13: #2888 | B13: =IF(ISNUMBER(C13),C13,DATEVALUE(SUBSTITUTE(TRIM(C13),CHAR(160)," "))) -> 46238.583 | C13: 46238.583 | D13: Frederick Bean | E13: =IF(TRIM(F13)="","Missing Email","Email Available") -> Email Available | F13: frederick.bean141@outlook.com | G13: Leather Wallet - Brown | H13: Accessories | I13: ACC-WLT-BRN | J13: -2 | K13: 19.99 | M13: 0 | N13: 7.99 | O13: 47.97 | P13: Google Pay | Q13: Online Store | R13: pending | S13: United States | T13: California | U13: =IF(AND(S13="United States",T13=""),"Missing state",IF(T13="","Not Required","Valid")) -> Valid | V13: Barnesville
A14: #1003 | B14: =IF(ISNUMBER(C14),C14,DATEVALUE(SUBSTITUTE(TRIM(C14),CHAR(160)," "))) -> 46238.58 | C14: 46238.58 | D14: THOMAS ROJAS | E14: =IF(TRIM(F14)="","Missing Email","Email Available") -> Email Available | F14: thomas.rojas667@icloud.com | G14: Slim Fit Denim Jeans | H14: Apparel | I14: JNS-BLU-32 | J14: 1 | K14: 39.99 | M14: 0 | N14: 5.99 | O14: 45.98 | P14: Credit Card | Q14: Online Store | R14: fulfilled | S14: United States | T14: North Carolina | U14: =IF(AND(S14="United States",T14=""),"Missing state",IF(T14="","Not Required","Valid")) -> Valid | V14: West Cynthialand
A15: #1027 | B15: =IF(ISNUMBER(C15),C15,DATEVALUE(SUBSTITUTE(TRIM(C15),CHAR(160)," "))) -> 46238.583 | C15: 46238.583 | D15: Sandra Wilson | E15: =IF(TRIM(F15)="","Missing Email","Email Available") -> Email Available | F15: sandra.wilson554@outlook.com | G15: Vitamin C Serum 30ml | H15: Beauty | I15: BTY-SRM-30 | J15: 1 | K15: 24.99 | L15: VIP15 | M15: 3.75 | N15: 7.99 | O15: 29.23 | P15: Apple Pay | Q15: Online Store | R15: pending | S15: Canada | U15: =IF(AND(S15="United States",T15=""),"Missing state",IF(T15="","Not Required","Valid")) -> Not Required | V15: Hollyport
A16: #1172 | B16: =IF(ISNUMBER(C16),C16,DATEVALUE(SUBSTITUTE(TRIM(C16),CHAR(160)," "))) -> 46238.584 | C16: 46238.584 | D16: TINA SINGH | E16: =IF(TRIM(F16)="","Missing Email","Email Available") -> Email Available | F16: tina.singh98@icloud.com | G16: Leather Wallet - Brown | H16: Accessories | I16: ACC-WLT-BRN | J16: 1 | K16: 19.99 | M16: 0 | N16: 5.99 | O16: 25.98 | P16: Credit Card | Q16: Online Store | R16: fulfilled | S16: United States | T16: Washington | U16: =IF(AND(S16="United States",T16=""),"Missing state",IF(T16="","Not Required","Valid")) -> Valid | V16: East Heathertown
A17: #1260 | B17: =IF(ISNUMBER(C17),C17,DATEVALUE(SUBSTITUTE(TRIM(C17),CHAR(160)," "))) -> 46238.586 | C17: 46238.586 | D17: Morgan Brown | E17: =IF(TRIM(F17)="","Missing Email","Email Available") -> Email Available | F17: morgan.brown933@gmail.com | G17: Wireless Bluetooth Earbuds | H17: Electronics | I17: ELC-WBE-01 | J17: 1 | K17: 29.99 | L17: FREESHIP | M17: 0 | N17: 0 | O17: 29.99 | P17: Apple Pay | Q17: Online Store | R17: pending | S17: United States | T17: Florida | U17: =IF(AND(S17="United States",T17=""),"Missing state",IF(T17="","Not Required","Valid")) -> Valid | V17: Austinbury
A18: #1262 | B18: =IF(ISNUMBER(C18),C18,DATEVALUE(SUBSTITUTE(TRIM(C18),CHAR(160)," "))) -> 46238.586 | C18: 46238.586 | D18: Mark Mata | E18: =IF(TRIM(F18)="","Missing Email","Email Available") -> Email Available | F18: mark.mata757@outlook.com | G18: Facial Cleanser 200ml | H18: Beauty | I18: BTY-CLN-200 | J18: 1 | K18: 13.49 | M18: 0 | N18: 7.99 | O18: 21.48 | P18: Apple Pay | Q18: Facebook | R18: pending | S18: United States | T18: Washington | U18: =IF(AND(S18="United States",T18=""),"Missing state",IF(T18="","Not Required","Valid")) -> Valid | V18: Davidburgh
A19: #1305 | B19: =IF(ISNUMBER(C19),C19,DATEVALUE(SUBSTITUTE(TRIM(C19),CHAR(160)," "))) -> 46238.586 | C19: 46238.586 | D19: Amy Maldonado | E19: =IF(TRIM(F19)="","Missing Email","Email Available") -> Email Available | F19: amy.maldonado44@gmail.com | G19: Polarized Sunglasses | H19: Accessories | I19: ACC-SUN-01 | J19: 1 | K19: 16.99 | M19: 0 | N19: 5.99 | O19: 22.98 | P19: PayPal | Q19: Online Store | R19: fulfilled | S19: Pakistan | U19: =IF(AND(S19="United States",T19=""),"Missing state",IF(T19="","Not Required","Valid")) -> Not Required | V19: Matthewstad
A20: #1652 | B20: =IF(ISNUMBER(C20),C20,DATEVALUE(SUBSTITUTE(TRIM(C20),CHAR(160)," "))) -> 46238.585 | C20: 46238.585 | D20: Sean Frank | E20: =IF(TRIM(F20)="","Missing Email","Email Available") -> Email Available | F20: sean.frank587@icloud.com | G20: Kids Building Blocks Set | H20: Toys | I20: TOY-BLK-SET | J20: 2 | K20: 27.99 | L20: WELCOME10 | M20: 5.6 | N20: 7.99 | O20: $58.37 | P20: Credit Card | Q20: Facebook | R20: fulfilled | S20: Australia | U20: =IF(AND(S20="United States",T20=""),"Missing state",IF(T20="","Not Required","Valid")) -> Not Required | V20: Port Josephborough
A21: #1719 | B21: =IF(ISNUMBER(C21),C21,DATEVALUE(SUBSTITUTE(TRIM(C21),CHAR(160)," "))) -> 46238.589 | C21: 46238.589 | D21: GRACE RAY | E21: =IF(TRIM(F21)="","Missing Email","Email Available") -> Email Available | F21: grace.ray807@yahoo.com | G21: Wireless Mouse | H21: Electronics | I21: ELC-MSE-WL | J21: 2 | K21: 11.99 | M21: 0 | N21: 7.99 | O21: 31.97 | P21: Apple Pay | Q21: Facebook | R21: cancelled | S21: United Kingdom | U21: =IF(AND(S21="United States",T21=""),"Missing state",IF(T21="","Not Required","Valid")) -> Not Required | V21: Lutzton
A22: #1781 | B22: =DATE(VALUE(RIGHT(C22,4)),MATCH(LEFT(C22,3),{"Jan","Feb","Mar","Apr","May","Jun","Jul","Aug","Sep","Oct","Nov","Dec"},0),VALUE(MID(C22,5,2))) -> 46238 | C22: Aug 04, 2026 | D22: Sharon Brown | E22: =IF(TRIM(F22)="","Missing Email","Email Available") -> Missing Email | G22: Running Shoes - Men's | H22: Footwear | I22: FTW-RUN-M | J22: 1 | K22: 54.99 | M22: 0 | N22: 4.99 | O22: 59.98 | P22: Shopify Payments | Q22: POS | R22: fulfilled | S22: United States | T22: Arizona | U22: =IF(AND(S22="United States",T22=""),"Missing state",IF(T22="","Not Required","Valid")) -> Valid | V22: Clarkmouth
A23: #1798 | B23: =IF(ISNUMBER(C23),C23,DATEVALUE(SUBSTITUTE(TRIM(C23),CHAR(160)," "))) -> 46238.582 | C23: 46238.582 | D23: Tina Singh | E23: =IF(TRIM(F23)="","Missing Email","Email Available") -> Email Available | F23: tina.singh98@icloud.com | G23: Adjustable Dumbbell Set | H23: Sports & Outdoors | I23: SP-DMB-ADJ | J23: 2 | K23: 89.99 | M23: 0 | N23: 0 | O23: 179.98 | P23: Google Pay | Q23: POS | R23: pending | S23: United States | T23: Georgia | U23: =IF(AND(S23="United States",T23=""),"Missing state",IF(T23="","Not Required","Valid")) -> Valid | V23: North Shannon
A24: #1818 | B24: =IF(ISNUMBER(C24),C24,DATEVALUE(SUBSTITUTE(TRIM(C24),CHAR(160)," "))) -> 46120 | C24: 08/04/2026 | D24: Amanda Harris | E24: =IF(TRIM(F24)="","Missing Email","Email Available") -> Email Available | F24: amanda.harris197@gmail.com | G24: USB-C Fast Charger 20W | H24: Electronics | I24: ELC-CHG-20 | J24: 1 | K24: 15.49 | M24: 0 | N24: 5.99 | O24: 21.48 | P24: Google Pay | Q24: Instagram | R24: pending | S24: United States | T24: Washington | U24: =IF(AND(S24="United States",T24=""),"Missing state",IF(T24="","Not Required","Valid")) -> Valid | V24: Richardsonburgh
A25: #1859 | B25: =IF(ISNUMBER(C25),C25,DATEVALUE(SUBSTITUTE(TRIM(C25),CHAR(160)," "))) -> 46238.58 | C25: 46238.58 | D25: Sarah Webb | E25: =IF(TRIM(F25)="","Missing Email","Email Available") -> Email Available | F25: sarah.webb997@outlook.com | G25: Adjustable Dumbbell Set | H25: Sports & Outdoors | I25: SP-DMB-ADJ | J25: 3 | K25: 89.99 | L25: VIP15 | M25: 40.5 | N25: 0 | O25: 229.47 | P25: PayPal | Q25: Facebook | R25: fulfilled | S25: Germany | U25: =IF(AND(S25="United States",T25=""),"Missing state",IF(T25="","Not Required","Valid")) -> Not Required | V25: North Ronald
A26: #1866 | B26: =IF(ISNUMBER(C26),C26,DATEVALUE(SUBSTITUTE(TRIM(C26),CHAR(160)," "))) -> 46238.579 | C26: 46238.579 | D26: Melissa Jones | E26: =IF(TRIM(F26)="","Missing Email","Email Available") -> Missing Email | G26: Ceramic Coffee Mug Set (4pc) | H26: Home & Kitchen | I26: HK-MUG-4PK | J26: 1 | K26: 18.99 | L26: FREESHIP | M26: 0 | N26: 0 | O26: 18.99 | P26: Credit Card | Q26: Online Store | R26: pending | S26: United States | T26: Florida | U26: =IF(AND(S26="United States",T26=""),"Missing state",IF(T26="","Not Required","Valid")) -> Valid | V26: Kelseybury
A27: #1948 | B27: =IF(ISNUMBER(C27),C27,DATEVALUE(SUBSTITUTE(TRIM(C27),CHAR(160)," "))) -> 46238.582 | C27: 46238.582 | D27: Peter Alvarez | E27: =IF(TRIM(F27)="","Missing Email","Email Available") -> Email Available | F27: peter.alvarez465@yahoo.com | G27: Wireless Mouse | H27: Electronics | I27: ELC-MSE-WL | J27: 1 | K27: 11.99 | L27: VIP15 | M27: 1.8 | N27: 5.99 | O27: 16.18 | P27: PayPal | Q27: Online Store | R27: fulfilled | S27: United States | T27: Illinois | U27: =IF(AND(S27="United States",T27=""),"Missing state",IF(T27="","Not Required","Valid")) -> Valid | V27: New Jeffreystad
A28: #1963 | B28: =IF(ISNUMBER(C28),C28,DATEVALUE(SUBSTITUTE(TRIM(C28),CHAR(160)," "))) -> 46238 | C28: 04-08-2026 13:58 | D28: Sean Frank | E28: =IF(TRIM(F28)="","Missing Email","Email Available") -> Email Available | F28: sean.frank587@icloud.com | G28: Yoga Mat - Extra Thick | H28: Sports & Outdoors | I28: SP-YGM-EX | J28: 1 | K28: 22.99 | L28: VIP15 | M28: 3.45 | N28: 7.99 | O28: 27.53 | P28: Credit Card | Q28: Online Store | R28: fulfilled | S28: Australia | U28: =IF(AND(S28="United States",T28=""),"Missing state",IF(T28="","Not Required","Valid")) -> Not Required | V28: New Bruce
A29: #2040 | B29: =IF(ISNUMBER(C29),C29,DATEVALUE(SUBSTITUTE(TRIM(C29),CHAR(160)," "))) -> 46238.579 | C29: 46238.579 | D29: Sean Frank | E29: =IF(TRIM(F29)="","Missing Email","Email Available") -> Email Available | F29: sean.frank587@icloud.com | G29: Stainless Steel Water Bottle | H29: Home & Kitchen | I29: HK-BTL-750 | J29: 1 | K29: 12.99 | L29: VIP15 | M29: 1.95 | N29: 7.99 | O29: 19.03 | P29: PayPal | Q29: Facebook | R29: fulfilled | S29: Australia | U29: =IF(AND(S29="United States",T29=""),"Missing state",IF(T29="","Not Required","Valid")) -> Not Required | V29: Thompsonburgh
A30: #2130 | B30: =IF(ISNUMBER(C30),C30,DATEVALUE(SUBSTITUTE(TRIM(C30),CHAR(160)," "))) -> 46238.586 | C30: 46238.586 | D30: Jacqueline Graham | E30: =IF(TRIM(F30)="","Missing Email","Email Available") -> Email Available | F30: jacqueline.graham958@gmail.com | G30: Phone Case - Clear | H30: Electronics | I30: ELC-CSE-CLR | J30: 1 | K30: 8.99 | M30: 0 | N30: 5.99 | O30: 14.98 | P30: Shopify Payments | Q30: POS | R30: refunded | S30: Australia | U30: =IF(AND(S30="United States",T30=""),"Missing state",IF(T30="","Not Required","Valid")) -> Not Required | V30: West Jeffreystad
A31: #2204 | B31: =IF(ISNUMBER(C31),C31,DATEVALUE(SUBSTITUTE(TRIM(C31),CHAR(160)," "))) -> 46120 | C31: 08/04/2026 | D31: Maria Patterson | E31: =IF(TRIM(F31)="","Missing Email","Email Available") -> Email Available | F31: maria.patterson62@icloud.com | G31: Yoga Mat - Extra Thick | H31: Sports & Outdoors | I31: SP-YGM-EX | J31: 1 | K31: 22.99 | L31: VIP15 | M31: 3.45 | N31: 5.99 | O31: 25.53 | P31: Credit Card | Q31: Instagram | R31: cancelled | S31: United States | T31: Texas | U31: =IF(AND(S31="United States",T31=""),"Missing state",IF(T31="","Not Required","Valid")) -> Valid | V31: West Ericport
A32: #2212 | B32: =IF(ISNUMBER(C32),C32,DATEVALUE(SUBSTITUTE(TRIM(C32),CHAR(160)," "))) -> 46238.585 | C32: 46238.585 | D32: Anthony Patterson | E32: =IF(TRIM(F32)="","Missing Email","Email Available") -> Email Available | F32: anthony.patterson944@gmail.com | G32: Scented Soy Candle - Vanilla | H32: Home & Kitchen | I32: HK-CND-VAN | J32: 1 | K32: 9.99 | L32: BFCM25 | M32: 2.5 | N32: 4.99 | O32: 12.48 | P32: Shopify Payments | Q32: Instagram | R32: refunded | S32: Pakistan | U32: =IF(AND(S32="United States",T32=""),"Missing state",IF(T32="","Not Required","Valid")) -> Not Required | V32: Josephbury
A33: #2331 | B33: =IF(ISNUMBER(C33),C33,DATEVALUE(SUBSTITUTE(TRIM(C33),CHAR(160)," "))) -> 46238 | C33: 04-08-2026 13:55 | D33: Taylor Davis | E33: =IF(TRIM(F33)="","Missing Email","Email Available") -> Email Available | F33: taylor.davis403@outlook.com | G33: Scented Soy Candle - Vanilla | H33: Home & Kitchen | I33: HK-CND-VAN | J33: 2 | K33: $9.99 | L33: freeship | M33: 0 | N33: 0 | O33: 19.98 | P33: PayPal | Q33: Online Store | R33: fulfilled | S33: United States | T33: Florida | U33: =IF(AND(S33="United States",T33=""),"Missing state",IF(T33="","Not Required","Valid")) -> Valid | V33: East Rhonda
A34: #2402 | B34: =IF(ISNUMBER(C34),C34,DATEVALUE(SUBSTITUTE(TRIM(C34),CHAR(160)," "))) -> 46238.587 | C34: 46238.587 | D34: Dustin Mccoy | E34: =IF(TRIM(F34)="","Missing Email","Email Available") -> Email Available | F34: dustin.mccoy570@gmail.com | G34: Running Shoes - Men's | H34: Footwear | I34: FTW-RUN-M | J34: 1 | K34: 54.99 | M34: 0 | N34: 5.99 | O34: 60.98 | P34: PayPal | Q34: Online Store | R34: fulfilled | S34: Canada | U34: =IF(AND(S34="United States",T34=""),"Missing state",IF(T34="","Not Required","Valid")) -> Not Required | V34: Lake Mariatown
A35: #2415 | B35: =IF(ISNUMBER(C35),C35,DATEVALUE(SUBSTITUTE(TRIM(C35),CHAR(160)," "))) -> 46238.58 | C35: 46238.58 | D35: Vincent Rosales | E35: =IF(TRIM(F35)="","Missing Email","Email Available") -> Email Available | F35: vincent.rosales30@icloud.com | G35: Scented Soy Candle - Vanilla | H35: Home & Kitchen | I35: HK-CND-VAN | J35: 2 | K35: 9.99 | L35: FREESHIP | M35: 0 | N35: 0 | O35: 19.98 | P35: PayPal | Q35: Online Store | R35: pending | S35: United States | T35: Texas | U35: =IF(AND(S35="United States",T35=""),"Missing state",IF(T35="","Not Required","Valid")) -> Valid | V35: Stephaniebury
A36: #2436 | B36: =IF(ISNUMBER(C36),C36,DATEVALUE(SUBSTITUTE(TRIM(C36),CHAR(160)," "))) -> 46238.583 | C36: 46238.583 | D36: David Fleming | E36: =IF(TRIM(F36)="","Missing Email","Email Available") -> Email Available | F36: david.fleming778@gmail.com | G36: USB-C Fast Charger 20W | H36: Electronics | I36: ELC-CHG-20 | J36: 1 | K36: 15.49 | M36: 0 | N36: 4.99 | O36: 20.48 | P36: PayPal | Q36: Instagram | R36: fulfilled | S36: Australia | U36: =IF(AND(S36="United States",T36=""),"Missing state",IF(T36="","Not Required","Valid")) -> Not Required | V36: Port Dustin
A37: #2502 | B37: =IF(ISNUMBER(C37),C37,DATEVALUE(SUBSTITUTE(TRIM(C37),CHAR(160)," "))) -> 46238 | C37: 04-08-2026 13:57 | D37: Barbara Brown | E37: =IF(TRIM(F37)="","Missing Email","Email Available") -> Email Available | F37: barbara.brown26@gmail.com | G37: Slim Fit Denim Jeans | H37: Apparel | I37: JNS-BLU-32 | J37: 1 | K37: 39.99 | L37: VIP15 | M37: 6 | N37: 7.99 | O37: 41.98 | P37: Google Pay | Q37: Instagram | R37: refunded | S37: United States | T37: California | U37: =IF(AND(S37="United States",T37=""),"Missing state",IF(T37="","Not Required","Valid")) -> Valid | V37: North Benjamintown
A38: #2545 | B38: =IF(ISNUMBER(C38),C38,DATEVALUE(SUBSTITUTE(TRIM(C38),CHAR(160)," "))) -> 46238.587 | C38: 46238.587 | D38: Courtney Bullock | E38: =IF(TRIM(F38)="","Missing Email","Email Available") -> Email Available | F38: courtney.bullock860@outlook.com | G38: Ceramic Coffee Mug Set (4pc) | H38: Home & Kitchen | I38: HK-MUG-4PK | J38: 1 | K38: 18.99 | L38: FREESHIP | M38: 0 | N38: 0 | O38: 18.99 | P38: Google Pay | Q38: Instagram | R38: fulfilled | S38: United Kingdom | U38: =IF(AND(S38="United States",T38=""),"Missing state",IF(T38="","Not Required","Valid")) -> Not Required | V38: South Savannahton
A39: #2581 | B39: =IF(ISNUMBER(C39),C39,DATEVALUE(SUBSTITUTE(TRIM(C39),CHAR(160)," "))) -> 46238.586 | C39: 46238.586 | D39: Lindsay Shaw | E39: =IF(TRIM(F39)="","Missing Email","Email Available") -> Email Available | F39: lindsay.shaw178@icloud.com | G39: Leather Wallet - Brown | H39: Accessories | I39: ACC-WLT-BRN | J39: 1 | K39: 19.99 | M39: 0 | N39: 4.99 | O39: 24.98 | P39: Google Pay | Q39: Online Store | R39: refunded | S39: United Kingdom | U39: =IF(AND(S39="United States",T39=""),"Missing state",IF(T39="","Not Required","Valid")) -> Not Required | V39: Campbellmouth
A40: #2603 | B40: =IF(ISNUMBER(C40),C40,DATEVALUE(SUBSTITUTE(TRIM(C40),CHAR(160)," "))) -> 46120 | C40: 08/04/2026 | D40: Amanda Harris | E40: =IF(TRIM(F40)="","Missing Email","Email Available") -> Missing Email | G40: Polarized Sunglasses | H40: Accessories | I40: ACC-SUN-01 | J40: 1 | K40: 16.99 | M40: 0 | N40: 7.99 | O40: 24.98 | P40: Apple Pay | Q40: POS | R40: cancelled | S40: United States | T40: New York | U40: =IF(AND(S40="United States",T40=""),"Missing state",IF(T40="","Not Required","Valid")) -> Valid | V40: Lake Steven
...
